Workbook

Sheet Cover
A2: A regional revenue forecast, scenario analysis, and variance review for Netflix, built from public SEC filings.
A3: Matthew Franklin — 8/7/2026 — Covers Q1'21 actuals through Q1'27 forecast
A5: CONTENTS
A6: Tab | B6: Color | C6: What it contains
A7: Historical | B7: Blue | C7: 21 quarters of real, sourced financial data (Q1'21–Q1'26)
A8: Assumptions | B8: Blue | C8: Forecast growth rates and margin assumptions, with rationale
A9: Revenue Build | B9: Green | C9: Formula-driven revenue forecast, tied out against actuals
A10: P&L | B10: Green | C10: Full P&L at the operating-margin level, historical + forecast
A11: Scenario | B11: Green | C11: Base/Bull/Bear toggle, feeds Revenue Build and P&L
A12: Variance | B12: Green | C12: Q2'26 forecast vs. actual, with a full bridge analysis
A13: Dashboard | B13: Orange | C13: Four charts summarizing the whole model at a glance
A15: Tab names link straight to each sheet. Color grouping: blue = source data and inputs; green = calculation engine; orange = output/reporting.
A17: HEADLINE RESULT — Q2'26 FORECAST VS. ACTUAL
A18: ="• Revenue: forecast "&TEXT(Variance!B26,"$#,##0")&"M vs. actual "&TEXT(Variance!C26,"$#,##0")&"M — a miss of "&TEXT(ABS(Variance!D26),"$#,##0")&"M ("&TEXT(Variance!E26,"0.0%")&")" -> • Revenue: forecast $12,707M vs. actual $12,560M — a miss of $147M (-1.2%)
A19: ="• Operating margin: forecast "&TEXT(Variance!B27,"0.0%")&" vs. actual "&TEXT(Variance!C27,"0.0%")&" — "&TEXT(Variance!D27*100,"+0.0;-0.0")&"pp" -> • Operating margin: forecast 30.0% vs. actual 33.4% — +3.4pp
A20: ="• Operating income: forecast "&TEXT(Variance!B28,"$#,##0")&"M vs. actual "&TEXT(Variance!C28,"$#,##0")&"M — a beat of "&TEXT(Variance!D28,"$#,##0")&"M ("&TEXT(Variance!E28,"+0.0%")&")" -> • Operating income: forecast $3,812M vs. actual $4,193M — a beat of $381M (+10.0%)
A22: ="The revenue miss was more than offset by margin outperformance — "&TEXT(ABS(Variance!B31),"$#,##0")&"M of revenue drag against "&TEXT(Variance!B32,"$#,##0")&"M of margin benefit, netting a "&TEXT(Variance!B33,"$#,##0")&"M operating income beat." -> The revenue miss was more than offset by margin outperformance — $44M of revenue drag against $425M of margin benefit, netting a $381M operating income beat.
A24: METHODOLOGY & JUDGMENT CALLS
A25: Built from Netflix's 8-K shareholder letters and 10-Q/10-K filings. Revenue is modeled by regional growth rate, because Netflix no longer discloses regional subscriber or ARPU splits. The P&L is built at the operating-margin level rather than full expense line items, for the same disclosure reason. Historical per-share data is adjusted for Netflix's November 2025 10-for-1 stock split, and the model flags a one-time $2.8B non-operating item in Q1'26 (the Warner Bros. Discovery merger termination fee) so it does not distort operating trends.

Sheet Assumptions
A1: NETFLIX FORECAST ASSUMPTIONS
A2: Regional revenue growth model - Netflix does not disclose regional subscriber/ARPU splits, so growth is modeled off Y/Y % revenue growth by region, calculated from the Historical tab
A4: HISTORICAL GROWTH RATES (Y/Y %)
A5: Region | B5: Q1'22 | C5: Q2'22 | D5: Q3'22 | E5: Q4'22 | F5: Q1'23 | G5: Q2'23 | H5: Q3'23 | I5: Q4'23 | J5: Q1'24 | K5: Q2'24 | L5: Q3'24 | M5: Q4'24 | N5: Q1'25 | O5: Q2'25 | P5: Q3'25 | Q5: Q4'25 | R5: Q1'26
A6: UCAN | B6: =Historical!F6/Historical!B6-1 -> 0.05644907 | C6: =Historical!G6/Historical!C6-1 -> 0.09366306 | D6: =Historical!H6/Historical!D6-1 -> 0.10558625 | E6: =Historical!I6/Historical!E6-1 -> 0.086430946 | F6: =Historical!J6/Historical!F6-1 -> 0.077313433 | G6: =Historical!K6/Historical!G6-1 -> 0.017241379 | H6: =Historical!L6/Historical!H6-1 -> 0.036923931 | I6: =Historical!M6/Historical!I6-1 -> 0.093463143 | ... R6: =Historical!V6/Historical!R6-1 -> 0.13601906
A7: EMEA | B7: =Historical!F7/Historical!B7-1 -> 0.093003413 | C7: =Historical!G7/Historical!C7-1 -> 0.02375 | D7: =Historical!H7/Historical!D7-1 -> -0.023026316 | E7: =Historical!I7/Historical!E7-1 -> -0.068569164 | F7: =Historical!J7/Historical!F7-1 -> -0.017174083 | G7: =Historical!K7/Historical!G7-1 -> 0.042735043 | H7: =Historical!L7/Historical!H7-1 -> 0.13341751 | I7: =Historical!M7/Historical!I7-1 -> 0.18468085 | ... R7: =Historical!V7/Historical!R7-1 -> 0.17415565
A8: LATAM | B8: =Historical!F8/Historical!B8-1 -> 0.19354839 | C8: =Historical!G8/Historical!C8-1 -> 0.19628339 | D8: =Historical!H8/Historical!D8-1 -> 0.11912568 | E8: =Historical!I8/Historical!E8-1 -> 0.054979253 | F8: =Historical!J8/Historical!F8-1 -> 0.071071071 | G8: =Historical!K8/Historical!G8-1 -> 0.045631068 | H8: =Historical!L8/Historical!H8-1 -> 0.11621094 | I8: =Historical!M8/Historical!I8-1 -> 0.1366765 | ... R8: =Historical!V8/Historical!R8-1 -> 0.18621236
A9: APAC | B9: =Historical!F9/Historical!B9-1 -> 0.20341207 | C9: =Historical!G9/Historical!C9-1 -> 0.13642053 | D9: =Historical!H9/Historical!D9-1 -> 0.065947242 | E9: =Historical!I9/Historical!E9-1 -> -0.016073479 | F9: =Historical!J9/Historical!F9-1 -> 0.018538713 | G9: =Historical!K9/Historical!G9-1 -> 0.012114537 | H9: =Historical!L9/Historical!H9-1 -> 0.066366704 | I9: =Historical!M9/Historical!I9-1 -> 0.12368728 | ... R9: =Historical!V9/Historical!R9-1 -> 0.19857029
A12: FORECAST GROWTH RATE ASSUMPTIONS (Y/Y %)
A13: Region | B13: Q2'26 | C13: Q3'26 | D13: Q4'26 | E13: Q1'27 | G13: Rationale
A14: UCAN | B14: 0.12 | C14: 0.11 | D14: 0.1 | E14: 0.1 | G14: Q1'26 actual was 13.6%. Assuming gradual deceleration toward 10% as ad-tier penetration matures, management has flagged ad-tier scaling as a maturing growth driver, not a new one.
A15: EMEA | B15: 0.16 | C15: 0.15 | D15: 0.15 | E15: 0.14 | G15: Recent quarters (17-18% reported) run well ahead of FX-neutral growth (~12% per Q1'26 letter). Forecast holds reported-basis trend but tapers slightly, since the reported/FX-neutral gap is a currency effect, not durable growth.
A16: LATAM | B16: 0.17 | C16: 0.16 | D16: 0.15 | E16: 0.15 | G16: Clear acceleration Q3'25 (10.5%) to Q1'26 (18.6%). Keeping growth strong but tapering the rate of acceleration, since a jump this sharp in one quarter is often partly a one-time driver (pricing, content) rather than a new sustained pace.
A17: APAC | B17: 0.19 | C17: 0.18 | D17: 0.18 | E17: 0.17 | G17: No clean trend Q1'22-Q1'26 (ranges from -1.6% to 25.9%); anchoring near the recent 4-quarter average (~19%) rather than extending a noisy pattern in either direction.
A19: GUIDANCE CHECK
A20: Region | B20: 2025 Actual Rev($M) | C20: Avg Fcst Growth | D20: 2026E Rev ($M)
A21: UCAN | B21: =SUM(Historical!R6:U6) -> 19957 | C21: =AVERAGE(B14:E14) -> 0.1075 | D21: =B21*(1+C21) -> 22102.377
A22: EMEA | B22: =SUM(Historical!R7:U7) -> 14515 | C22: =AVERAGE(B15:E15) -> 0.15 | D22: =B22*(1+C22) -> 16692.25
A23: LATAM | B23: =SUM(Historical!R8:U8) -> 5358 | C23: =AVERAGE(B16:E16) -> 0.1575 | D23: =B23*(1+C23) -> 6201.885
A24: APAC | B24: =SUM(Historical!R9:U9) -> 5354 | C24: =AVERAGE(B17:E17) -> 0.18 | D24: =B24*(1+C24) -> 6317.72
A25: TOTAL | B25: =SUM(B21:B24) -> 45184 | D25: =SUM(D21:D24) -> 51314.233
A26: Implied 2026 growth: | B26: =(D25/B25)-1 -> 0.13567264 | C26: Netflix guidance: 12-14% ($50.7-51.7B)
A28: Result: bottoms-up build implies ~ 13.6% total 2026 revenue growth ($51,314M), which falls inside Netflix's own stated 12-14% guidance range($50.7-51.7B).
A30: OPERATING MARGIN ASSUMPTION (forecast, company-wide)
B31: Q2'26 | C31: Q3'26 | D31: Q4'26 | E31: Q1'27 | G31: Rationale
A32: Operating Margin % | B32: 0.3 | C32: 0.28 | D32: 0.25 | E32: 0.31 | G32: Trailing 4-quarter average (Q2'25-Q1'26) is ~29.8%. Adjusted for the seasonal pattern visible in 2024-2025 data: Q4 consistently runs lower (22.2% in Q4'24, 24.5% in Q4'25), Q1 consistently runs higher (31.7% in Q1'25, 32.3% in Q1'26).

Sheet Historical
A1: NETFLIX HISTORICAL FINANCIALS
A2: All figures in $M unless noted. Blue = hardcoded from filings. Black = formulas.
A4: Metric | B4: Q1'21 | C4: Q2'21 | D4: Q3'21 | E4: Q4'21 | F4: Q1'22 | G4: Q2'22 | H4: Q3'22 | I4: Q4'22 | J4: Q1'23 | K4: Q2'23 | L4: Q3'23 | M4: Q4'23 | N4: Q1'24 | O4: Q2'24 | P4: Q3'24 | Q4: Q4'24 | R4: Q1'25 | S4: Q2'25 | T4: Q3'25 | U4: Q4'25 | V4: Q1'26 | W4: Source
A5: REGIONAL REVENUE
A6: Revenue - UCAN | B6: 3171 | C6: 3235 | D6: 3258 | E6: 3309 | F6: 3350 | G6: 3538 | H6: 3602 | I6: 3595 | J6: 3609 | K6: 3599 | L6: 3735 | M6: 3931 | N6: 4224 | O6: 4296 | P6: 4322 | Q6: 4517 | R6: 4617 | S6: 4929 | T6: 5072 | U6: 5339 | V6: 5245 | W6: Confirmed: Q1'21-Q1'22 from Q1'22 8-K; Q2'22-Q2'23 from Q2'23 8-K; Q2'23-Q2'24 from Q2'24 8-K; Q3'24-Q3'25 from Q3'25 8-K; Q4'25 from Q4'25 8-K; Q1'26 from Q1'26 8-K
A7: Revenue - EMEA | B7: 2344 | C7: 2400 | D7: 2432 | E7: 2523 | F7: 2562 | G7: 2457 | H7: 2376 | I7: 2350 | J7: 2518 | K7: 2562 | L7: 2693 | M7: 2784 | N7: 2958 | O7: 3008 | P7: 3133 | Q7: 3288 | R7: 3405 | S7: 3538 | T7: 3699 | U7: 3873 | V7: 3998 | W7: Confirmed: Q1'21-Q1'22 from Q1'22 8-K; Q2'22-Q2'23 from Q2'23 8-K; Q2'23-Q2'24 from Q2'24 8-K; Q3'24-Q3'25 from Q3'25 8-K; Q4'25 from Q4'25 8-K; Q1'26 from Q1'26 8-K
A8: Revenue - LATAM | B8: 837 | C8: 861 | D8: 915 | E8: 964 | F8: 999 | G8: 1030 | H8: 1024 | I8: 1017 | J8: 1070 | K8: 1077 | L8: 1143 | M8: 1156 | N8: 1165 | O8: 1204 | P8: 1241 | Q8: 1230 | R8: 1262 | S8: 1307 | T8: 1371 | U8: 1418 | V8: 1497 | W8: Confirmed: Q1'21-Q1'22 from Q1'22 8-K; Q2'22-Q2'23 from Q2'23 8-K; Q2'23-Q2'24 from Q2'24 8-K; Q3'24-Q3'25 from Q3'25 8-K; Q4'25 from Q4'25 8-K; Q1'26 from Q1'26 8-K
A9: Revenue - APAC | B9: 762 | C9: 799 | D9: 834 | E9: 871 | F9: 917 | G9: 908 | H9: 889 | I9: 857 | J9: 934 | K9: 919 | L9: 948 | M9: 963 | N9: 1023 | O9: 1052 | P9: 1128 | Q9: 1212 | R9: 1259 | S9: 1305 | T9: 1369 | U9: 1421 | V9: 1509 | W9: Confirmed: Q1'21-Q1'22 from Q1'22 8-K; Q2'22-Q2'23 from Q2'23 8-K; Q2'23-Q2'24 from Q2'24 8-K; Q3'24-Q3'25 from Q3'25 8-K; Q4'25 from Q4'25 8-K; Q1'26 from Q1'26 8-K
A10: Total Revenue (Calculated) | B10: =SUM(B6:B9) -> 7114 | C10: =SUM(C6:C9) -> 7295 | D10: =SUM(D6:D9) -> 7439 | E10: =SUM(E6:E9) -> 7667 | F10: =SUM(F6:F9) -> 7828 | G10: =SUM(G6:G9) -> 7933 | H10: =SUM(H6:H9) -> 7891 | I10: =SUM(I6:I9) -> 7819 | ... V10: =SUM(V6:V9) -> 12249
A11: Reported Total Revenue (per 8-K) | B11: 7163 | C11: 7342 | D11: 7483 | E11: 7709 | F11: 7868 | G11: 7970 | H11: 7926 | I11: 7852 | J11: 8162 | K11: 8187 | L11: 8542 | M11: 8833 | N11: 9370 | O11: 9559 | P11: 9825 | Q11: 10247 | R11: 10543 | S11: 11079 | T11: 11510 | U11: 12051 | V11: 12249 | W11: Confirmed from Netflix quarterly 8-K summary tables, Q1'21-Q1'26
A12: Check (Calc - Reported, should be 0) | B12: =B10-B11 -> -49 | C12: =C10-C11 -> -47 | D12: =D10-D11 -> -44 | E12: =E10-E11 -> -42 | F12: =F10-F11 -> -40 | G12: =G10-G11 -> -37 | H12: =H10-H11 -> -35 | I12: =I10-I11 -> -33 | ... V12: =V10-V11 -> 0
A14: P&L SUMMARY
A15: Operating Income | B15: 1960 | C15: 1848 | D15: 1755 | E15: 632 | F15: 1972 | G15: 1578 | H15: 1533 | I15: 550 | J15: 1714 | K15: 1827 | L15: 1916 | M15: 1496 | N15: 2633 | O15: 2603 | P15: 2909 | Q15: 2273 | R15: 3347 | S15: 3775 | T15: 3248 | U15: 2957 | V15: 3957 | W15: Confirmed from Netflix quarterly 8-K summary tables, Q1'21-Q1'26
A16: Operating Margin % | B16: 0.274 | C16: 0.252 | D16: 0.235 | E16: 0.082 | F16: 0.251 | G16: 0.198 | H16: 0.193 | I16: 0.07 | J16: 0.21 | K16: 0.223 | L16: 0.224 | M16: 0.169 | N16: 0.281 | O16: 0.272 | P16: 0.296 | Q16: 0.222 | R16: 0.317 | S16: 0.341 | T16: 0.282 | U16: 0.245 | V16: 0.323 | W16: Confirmed from Netflix quarterly 8-K summary tables, Q1'21-Q1'26
A17: Net Income | B17: 1707 | C17: 1353 | D17: 1449 | E17: 607 | F17: 1597 | G17: 1441 | H17: 1398 | I17: 55 | J17: 1305 | K17: 1488 | L17: 1677 | M17: 938 | N17: 2332 | O17: 2147 | P17: 2364 | Q17: 1869 | R17: 2890 | S17: 3125 | T17: 2547 | U17: 2419 | V17: 5283 | W17: Confirmed from Netflix quarterly 8-K/10-Q; Q1'26 includes one-time $2.8B WBD termination fee (non-operating)
A18: Diluted ESP (split-adjusted) | B18: 0.38 | C18: 0.3 | D18: 0.32 | E18: 0.13 | F18: 0.35 | G18: 0.32 | H18: 0.31 | I18: 0.01 | J18: 0.29 | K18: 0.33 | L18: 0.37 | M18: 0.21 | N18: 0.53 | O18: 0.49 | P18: 0.54 | Q18: 0.43 | R18: 0.66 | S18: 0.72 | T18: 0.59 | U18: 0.56 | V18: 1.23 | W18: Netflix 8-Ks; Q3'24-Q3'25 restated /10 for 10-for-1 split effective 11/14/2025
A20: Note 1: Netflix executed a 10-for-1 stock split effective 11/14/2025. Diluted EPS for Q1'21-Q3'25 above is restated (divided by 10) to be comparable with Q4'25 onward. Note 2: Q1'26 Net Income ($5.28B) and EPS ($1.23) include a one-time $2.8B non-operating gain from a Warner Bros. Discovery merger termination fee - strip this out before using Q1'26 as a forecasting baseline. Note 3: the Check row is NOT exactly zero for Q1'21 through Q3'23 (off by $30-49M each quarter, shrinking over time) - this is real, not an error. The 'Regional Breakdown' table is labeled 'UCAN Streaming' and only covers streaming revenue; Netflix's legacy DVD-by-mail business (US-only, wound down through 2023) is included in the company-wide reported total but not in the four regional rows. The gap shrinks to exactly $0-1M by Q4'23/Q1'24, which lines up with Netflix officially closing the DVD business in September 2023 - a good example of a small, explainable tie-out gap versus an actual data error.

Sheet Revenue Build
A1: NETFLIX REVENUE BUILD
A2: Historical rebuild validates the growth-rate mechanic against actuals; forecast section extends the same formula into Q2'26-Q1'27
A4: HISTORICAL REBUILD (TIE-OUT CHECK)
A5: Region | B5: Q1'22 | C5: Q2'22 | D5: Q3'22 | E5: Q4'22 | F5: Q1'23 | G5: Q2'23 | H5: Q3'23 | I5: Q4'23 | J5: Q1'24 | K5: Q2'24 | L5: Q3'24 | M5: Q4'24 | N5: Q1'25 | O5: Q2'25 | P5: Q3'25 | Q5: Q4'25 | R5: Q1'26
A6: UCAN (calculated) | B6: =Historical!B6*(1+Assumptions!B6) -> 3350 | C6: =Historical!C6*(1+Assumptions!C6) -> 3538 | D6: =Historical!D6*(1+Assumptions!D6) -> 3602 | E6: =Historical!E6*(1+Assumptions!E6) -> 3595 | F6: =Historical!F6*(1+Assumptions!F6) -> 3609 | G6: =Historical!G6*(1+Assumptions!G6) -> 3599 | H6: =Historical!H6*(1+Assumptions!H6) -> 3735 | I6: =Historical!I6*(1+Assumptions!I6) -> 3931 | ... R6: =Historical!R6*(1+Assumptions!R6) -> 5245
A7: EMEA (calculated) | B7: =Historical!B7*(1+Assumptions!B7) -> 2562 | C7: =Historical!C7*(1+Assumptions!C7) -> 2457 | D7: =Historical!D7*(1+Assumptions!D7) -> 2376 | E7: =Historical!E7*(1+Assumptions!E7) -> 2350 | F7: =Historical!F7*(1+Assumptions!F7) -> 2518 | G7: =Historical!G7*(1+Assumptions!G7) -> 2562 | H7: =Historical!H7*(1+Assumptions!H7) -> 2693 | I7: =Historical!I7*(1+Assumptions!I7) -> 2784 | ... R7: =Historical!R7*(1+Assumptions!R7) -> 3998
A8: LATAM (calculated) | B8: =Historical!B8*(1+Assumptions!B8) -> 999 | C8: =Historical!C8*(1+Assumptions!C8) -> 1030 | D8: =Historical!D8*(1+Assumptions!D8) -> 1024 | E8: =Historical!E8*(1+Assumptions!E8) -> 1017 | F8: =Historical!F8*(1+Assumptions!F8) -> 1070 | G8: =Historical!G8*(1+Assumptions!G8) -> 1077 | H8: =Historical!H8*(1+Assumptions!H8) -> 1143 | I8: =Historical!I8*(1+Assumptions!I8) -> 1156 | ... R8: =Historical!R8*(1+Assumptions!R8) -> 1497
A9: APAC (calculated) | B9: =Historical!B9*(1+Assumptions!B9) -> 917 | C9: =Historical!C9*(1+Assumptions!C9) -> 908 | D9: =Historical!D9*(1+Assumptions!D9) -> 889 | E9: =Historical!E9*(1+Assumptions!E9) -> 857 | F9: =Historical!F9*(1+Assumptions!F9) -> 934 | G9: =Historical!G9*(1+Assumptions!G9) -> 919 | H9: =Historical!H9*(1+Assumptions!H9) -> 948 | I9: =Historical!I9*(1+Assumptions!I9) -> 963 | ... R9: =Historical!R9*(1+Assumptions!R9) -> 1509
A11: Total Revenue Build (calculated) | B11: =SUM(B6:B9) -> 7828 | C11: =SUM(C6:C9) -> 7933 | D11: =SUM(D6:D9) -> 7891 | E11: =SUM(E6:E9) -> 7819 | F11: =SUM(F6:F9) -> 8131 | G11: =SUM(G6:G9) -> 8157 | H11: =SUM(H6:H9) -> 8519 | I11: =SUM(I6:I9) -> 8834 | ... R11: =SUM(R6:R9) -> 12249
A12: Reported Total Revenue (per Historical tab) | B12: 7868 | C12: 7970 | D12: 7926 | E12: 7852 | F12: 8162 | G12: 8187 | H12: 8542 | I12: 8833 | J12: 9370 | K12: 9559 | L12: 9825 | M12: 10247 | N12: 10543 | O12: 11079 | P12: 11510 | Q12: 12051 | R12: 12249
A13: Check (Calc - Reported, should be ~0) | B13: =B11-B12 -> -40 | C13: =C11-C12 -> -37 | D13: =D11-D12 -> -35 | E13: =E11-E12 -> -33 | F13: =F11-F12 -> -31 | G13: =G11-G12 -> -30 | H13: =H11-H12 -> -23 | I13: =I11-I12 -> 1 | ... R13: =R11-R12 -> 0
A16: FORECAST (Q2'26-Q1'27)
A17: Region | B17: Q2'26 | C17: Q3'26 | D17: Q4'26 | E17: Q1'27
A18: UCAN | B18: {=Historical!S6:S9*(1+Scenario!B33:B36)} -> 5520.48 | C18: {=Historical!T6:T9*(1+Scenario!C33:C36)} -> 5629.92 | D18: {=Historical!U6:U9*(1+Scenario!D33:D36)} -> 5872.9 | E18: {=Historical!V6:V9*(1+Scenario!E33:E36)} -> 5769.5
A19: EMEA | B19: 4104.08 | C19: 4253.85 | D19: 4453.95 | E19: 4557.72
A20: LATAM | B20: 1529.19 | C20: 1590.36 | D20: 1630.7 | E20: 1721.55
A21: APAC | B21: 1552.95 | C21: 1615.42 | D21: 1676.78 | E21: 1765.53
A22: Total Revenue Build (forecast) | B22: =SUM(_xlfn.ANCHORARRAY(B18)) -> 12706.7 | C22: =SUM(_xlfn.ANCHORARRAY(C18)) -> 13089.55 | D22: =SUM(_xlfn.ANCHORARRAY(D18)) -> 13634.33 | E22: =SUM(_xlfn.ANCHORARRAY(E18)) -> 13814.3

Sheet P&L
A1: NETFLIX P&L SUMMARY
A2: "Built at the operating-margin level rather than full expense line items, since Netflix's quarterly letters don't disclose a cost of revenue/marketing/tech-dev/G&A breakdown — only the 10-Q/10-K full statements do, which weren't pulled for this build.
A4: HISTORICAL (Q1'21-Q1'26)
A5: Metric | B5: Q1'21 | C5: Q2'21 | D5: Q3'21 | E5: Q4'21 | F5: Q1'22 | G5: Q2'22 | H5: Q3'22 | I5: Q4'22 | J5: Q1'23 | K5: Q2'23 | L5: Q3'23 | M5: Q4'23 | N5: Q1'24 | O5: Q2'24 | P5: Q3'24 | Q5: Q4'24 | R5: Q1'25 | S5: Q2'25 | T5: Q3'25 | U5: Q4'25 | V5: Q1'26
A6: Total Revenue | B6: {=Historical!B11:V11} -> 7163 | C6: 7342 | D6: 7483 | E6: 7709 | F6: 7868 | G6: 7970 | H6: 7926 | I6: 7852 | J6: 8162 | K6: 8187 | L6: 8542 | M6: 8833 | N6: 9370 | O6: 9559 | P6: 9825 | Q6: 10247 | R6: 10543 | S6: 11079 | T6: 11510 | U6: 12051 | V6: 12249
A7: Total Operationg Expences | B7: {=B6:V6-B8:V8} -> 5203 | C7: 5494 | D7: 5728 | E7: 7077 | F7: 5896 | G7: 6392 | H7: 6393 | I7: 7302 | J7: 6448 | K7: 6360 | L7: 6626 | M7: 7337 | N7: 6737 | O7: 6956 | P7: 6916 | Q7: 7974 | R7: 7196 | S7: 7304 | T7: 8262 | U7: 9094 | V7: 8292
A8: Operating Income | B8: {=Historical!B15:V15} -> 1960 | C8: 1848 | D8: 1755 | E8: 632 | F8: 1972 | G8: 1578 | H8: 1533 | I8: 550 | J8: 1714 | K8: 1827 | L8: 1916 | M8: 1496 | N8: 2633 | O8: 2603 | P8: 2909 | Q8: 2273 | R8: 3347 | S8: 3775 | T8: 3248 | U8: 2957 | V8: 3957
A9: Operating Margin % | B9: {=B8:V8/B6:V6} -> 0.27362837 | C9: 0.25170253 | D9: 0.2345316 | E9: 0.081982099 | F9: 0.25063549 | G9: 0.19799247 | H9: 0.19341408 | I9: 0.070045848 | J9: 0.20999755 | K9: 0.22315867 | L9: 0.22430344 | M9: 0.16936488 | N9: 0.2810032 | O9: 0.27230882 | P9: 0.29608142 | Q9: 0.22182102 | R9: 0.31746182 | S9: 0.34073472 | T9: 0.2821894 | U9: 0.24537383 | V9: 0.32304678
A10: Non-Operating Items & Taxes, net | B10: {=B11:V11-B8:V8} -> -253 | C10: -495 | D10: -306 | E10: -25 | F10: -375 | G10: -137 | H10: -135 | I10: -495 | J10: -409 | K10: -339 | L10: -239 | M10: -558 | N10: -301 | O10: -456 | P10: -545 | Q10: -404 | R10: -457 | S10: -650 | T10: -701 | U10: -538 | V10: 1326
A11: Net Income | B11: {=Historical!B17:V17} -> 1707 | C11: 1353 | D11: 1449 | E11: 607 | F11: 1597 | G11: 1441 | H11: 1398 | I11: 55 | J11: 1305 | K11: 1488 | L11: 1677 | M11: 938 | N11: 2332 | O11: 2147 | P11: 2364 | Q11: 1869 | R11: 2890 | S11: 3125 | T11: 2547 | U11: 2419 | V11: 5283
A12: Net Margin % | B12: {=B11:V11/B6:V6} -> 0.23830797 | C12: 0.18428221 | D12: 0.19363891 | E12: 0.078739136 | F12: 0.20297407 | G12: 0.18080301 | H12: 0.17638153 | I12: 0.0070045848 | J12: 0.15988728 | K12: 0.18175156 | L12: 0.19632405 | M12: 0.10619269 | N12: 0.2488794 | O12: 0.22460508 | P12: 0.24061069 | Q12: 0.18239485 | R12: 0.27411553 | S12: 0.28206517 | T12: 0.22128584 | U12: 0.20073023 | V12: 0.43130051
A16: FORECAST (Q2'26-Q1'27)
A17: Metric | B17: Q2'26 | C17: Q3'26 | D17: Q4'26 | E17: Q1'27
A18: Total Revenue | B18: {='Revenue Build'!B22:E22} -> 12706.7 | C18: 13089.55 | D18: 13634.33 | E18: 13814.3
A19: Operating Margin Assumption | B19: =Scenario!B45 -> 0.3 | C19: =Scenario!C45 -> 0.28 | D19: =Scenario!D45 -> 0.25 | E19: =Scenario!E45 -> 0.31 | G19: Trailing 4Q avg ~29.8% (Q2'25-Q1'26), adjusted for seasonal pattern seen in 2024-2025 (Q4 lower, Q1 higher)
A20: Operating Income | B20: {=B18:E18*B19:E19} -> 3812.01 | C20: 3665.074 | D20: 3408.5825 | E20: 4282.433
A21: Net Income
A23: Net Income forecast omitted — Q1'26 alone shows a $2.8B one-time non-operating item; below-the-line items (taxes, interest, one-offs) are too unpredictable to forecast bottom-up reliably at this level of detail.

Sheet Scenario
A1: NETFLIX SCENARIO ANALYSIS
A2: Toggle switches P&L forecast between Base/Bull/Bear by flexing regional growth rates and operating margin. Selected scenario feeds the P&L tab.
A4: SELECTED SCENARIO: | B4: Base
A6: Growth rate flex (±pp): | B6: 0.03
A7: Margin flex (±pp): | B7: 0.02
A9: REGIONAL REVENUE GROWTH BY SCENARIO
A11: Base (reference: Assumptions tab)
A12: Region | B12: Q2'26 | C12: Q3'26 | D12: Q4'26 | E12: Q1'27
A13: UCAN | B13: {=Assumptions!B14:E17} -> 0.12 | C13: 0.11 | D13: 0.1 | E13: 0.1
A14: EMEA | B14: 0.16 | C14: 0.15 | D14: 0.15 | E14: 0.14
A15: LATAM | B15: 0.17 | C15: 0.16 | D15: 0.15 | E15: 0.15
A16: APAC | B16: 0.19 | C16: 0.18 | D16: 0.18 | E16: 0.17
A18: Bull (Base + growth flex)
A19: Region | B19: Q2'26 | C19: Q3'26 | D19: Q4'26 | E19: Q1'27
A20: UCAN | B20: {=B13:E16+B6} -> 0.15 | C20: 0.14 | D20: 0.13 | E20: 0.13
A21: EMEA | B21: 0.19 | C21: 0.18 | D21: 0.18 | E21: 0.17
A22: LATAM | B22: 0.2 | C22: 0.19 | D22: 0.18 | E22: 0.18
A23: APAC | B23: 0.22 | C23: 0.21 | D23: 0.21 | E23: 0.2
A25: Bear (Base - growth flex)
A26: Region | B26: Q2'26 | C26: Q3'26 | D26: Q4'26 | E26: Q1'27
A27: UCAN | B27: {=B13:E16-B6} -> 0.09 | C27: 0.08 | D27: 0.07 | E27: 0.07
A28: EMEA | B28: 0.13 | C28: 0.12 | D28: 0.12 | E28: 0.11
A29: LATAM | B29: 0.14 | C29: 0.13 | D29: 0.12 | E29: 0.12
A30: APAC | B30: 0.16 | C30: 0.15 | D30: 0.15 | E30: 0.14
A32: SELECTED GROWTH RATE (drives Revenue Build/P&L)
A33: UCAN | B33: {=IF($B$4="Base",_xlfn.ANCHORARRAY(B13), IF($B$4="Bull",_xlfn.ANCHORARRAY( B20),_xlfn.ANCHORARRAY( B27)))} -> 0.12 | C33: 0.11 | D33: 0.1 | E33: 0.1
A34: EMEA | B34: 0.16 | C34: 0.15 | D34: 0.15 | E34: 0.14
A35: LATAM | B35: 0.17 | C35: 0.16 | D35: 0.15 | E35: 0.15
A36: APAC | B36: 0.19 | C36: 0.18 | D36: 0.18 | E36: 0.17
A40: OPERATING MARGIN BY SCENARIO
A41: Scenario | B41: Q2'26 | C41: Q3'26 | D41: Q4'26 | E41: Q1'27
A42: Base | B42: {=Assumptions!B32:E32} -> 0.3 | C42: 0.28 | D42: 0.25 | E42: 0.31
A43: Bull | B43: {=B42:E42+B7} -> 0.32 | C43: 0.3 | D43: 0.27 | E43: 0.33
A44: Bear | B44: {=B42:E42-B7} -> 0.28 | C44: 0.26 | D44: 0.23 | E44: 0.29
A45: SELECTED | B45: {=IF($B$4="Base",_xlfn.ANCHORARRAY( B42), IF($B$4="Bull",_xlfn.ANCHORARRAY( B43),_xlfn.ANCHORARRAY( B44)))} -> 0.3 | C45: 0.28 | D45: 0.25 | E45: 0.31
A48: SCENARIO COMPARISON SUMMARY
A49: Metric / Scenario | B49: Q2'26 | C49: Q3'26 | D49: Q4'26 | E49: Q1'27
A50: Total Revenue - Bull | B50: {=SUMPRODUCT(Historical!S6:S9,(1+B20:B23))} -> 13039.07 | C50: {=SUMPRODUCT(Historical!T6:T9,(1+C20:C23))} -> 13434.88 | D50: {=SUMPRODUCT(Historical!U6:U9,(1+D20:D23))} -> 13995.86 | E50: {=SUMPRODUCT(Historical!V6:V9,(1+E20:E23))} -> 14181.77
A51: Total Revenue - Base | B51: {=SUMPRODUCT(Historical!S6:S9,(1+B13:B16))} -> 12706.7 | C51: {=SUMPRODUCT(Historical!T6:T9,(1+C13:C16))} -> 13089.55 | D51: {=SUMPRODUCT(Historical!U6:U9,(1+D13:D16))} -> 13634.33 | E51: {=SUMPRODUCT(Historical!V6:V9,(1+E13:E16))} -> 13814.3
A52: Total Revenue - Bear | B52: {=SUMPRODUCT(Historical!S6:S9,(1+B27:B30))} -> 12374.33 | C52: {=SUMPRODUCT(Historical!T6:T9,(1+C27:C30))} -> 12744.22 | D52: {=SUMPRODUCT(Historical!U6:U9,(1+D27:D30))} -> 13272.8 | E52: {=SUMPRODUCT(Historical!V6:V9,(1+E27:E30))} -> 13446.83
...

Sheet Variance
A1: NETFLIX VARIANCE ANALYSIS - Q2'26
A2: Compares the Base-case forecast (built Session 4-6) against Netflix's actual Q2'26 results, reported July 16 2026.
A4: REVENUE VARIANCE BY REGION
A5: Region | B5: Forecast (Base) | C5: Actual | D5: Variance ($M) | E5: Variance (%) | F5: Assumed Growth % (YoY) | G5: Actual Growth % (YoY) | H5: Growth Gap (pp)
A6: UCAN | B6: =Historical!S6*(1+F6) -> 5520.48 | C6: 5432 | D6: =C6-B6 -> -88.48 | E6: =D6/B6 -> -0.016027592 | F6: =Scenario!B13 -> 0.12 | G6: =C6/Historical!S6-1 -> 0.1020491 | H6: =(G6-F6)*100 -> -1.7950903
A7: EMEA | B7: =Historical!S7*(1+F7) -> 4104.08 | C7: 4034 | D7: =C7-B7 -> -70.08 | E7: =D7/B7 -> -0.017075691 | F7: =Scenario!B14 -> 0.16 | G7: =C7/Historical!S7-1 -> 0.1401922 | H7: =(G7-F7)*100 -> -1.9807801
A8: LATAM | B8: =Historical!S8*(1+F8) -> 1529.19 | C8: 1584 | D8: =C8-B8 -> 54.81 | E8: =D8/B8 -> 0.035842505 | F8: =Scenario!B15 -> 0.17 | G8: =C8/Historical!S8-1 -> 0.21193573 | H8: =(G8-F8)*100 -> 4.1935731
A9: APAC | B9: =Historical!S9*(1+F9) -> 1552.95 | C9: 1510 | D9: =C9-B9 -> -42.95 | E9: =D9/B9 -> -0.02765704 | F9: =Scenario!B16 -> 0.19 | G9: =C9/Historical!S9-1 -> 0.15708812 | H9: =(G9-F9)*100 -> -3.2911877
A10: TOTAL | B10: =SUM(B6:B9) -> 12706.7 | C10: =SUM(C6:C9) -> 12560 | D10: =C10-B10 -> -146.7 | E10: =D10/B10 -> -0.01154509 | F10: =B10/Historical!S10-1 -> 0.14691759 | G10: =C10/Historical!S10-1 -> 0.13367632 | H10: =(G10-F10)*100 -> -1.3241267
A12: Forecast (Base) = Q2'25 actual regional revenue × Base-case YoY growth from the Scenario tab; it stays on Base regardless of the scenario toggle. Growth Gap = actual YoY growth less assumed YoY growth, in percentage points.
A15: REVENUE BRIDGE
A16: Base Forecast Total | B16: =B10 -> 12706.7
A17: UCAN variance | B17: =D6 -> -88.48
A18: EMEA variance | B18: =D7 -> -70.08
A19: LATAM variance | B19: =D8 -> 54.81
A20: APAC variance | B20: =D9 -> -42.95
A21: Actual Total | B21: =SUM(B16:B20) -> 12560
A24: OPERATING MARGIN / INCOME VARIANCE
B25: Forecast (Base) | C25: Actual | D25: Variance | E25: Variance (%)
A26: Total Revenue ($M) | B26: =B10 -> 12706.7 | C26: =C10 -> 12560 | D26: =C26-B26 -> -146.7 | E26: =D26/B26 -> -0.01154509
A27: Operating Margin % | B27: =Scenario!B42 -> 0.3 | C27: =C28/C26 -> 0.33383758 | D27: =C27-B27 -> 0.03383758 | E27: =D27/B27 -> 0.11279193
A28: Operating Income ($M) | B28: =B26*B27 -> 3812.01 | C28: 4193 | D28: =C28-B28 -> 380.99 | E28: =D28/B28 -> 0.099944649
A30: OPERATING INCOME BRIDGE (Revenue effect vs. Margin effect)
A31: Revenue effect: (Actual Rev - Forecast Rev) x Forecast Margin | B31: =(C26-B26)*B27 -> -44.01
A32: Margin effect: (Actual Margin - Forecast Margin) x Actual Rev | B32: =(C27-B27)*C26 -> 425
A33: Total Operating Income Variance | B33: =B31+B32 -> 380.99
A34: Actual Operating Income Variance (check) | B34: =D28 -> 380.99

Sheet Dashboard
A1: NETFLIX FP&A DASHBOARD
A50: CHART DATA (helper tables - feed the dashboard charts; not for reading directly)
A52: Quarter | B52: =Historical!B4 -> Q1'21 | C52: =Historical!C4 -> Q2'21 | D52: =Historical!D4 -> Q3'21 | E52: =Historical!E4 -> Q4'21 | F52: =Historical!F4 -> Q1'22 | G52: =Historical!G4 -> Q2'22 | H52: =Historical!H4 -> Q3'22 | I52: =Historical!I4 -> Q4'22 | ... V52: =Historical!V4 -> Q1'26 | W52: ='Revenue Build'!B17 -> Q2'26 | X52: ='Revenue Build'!C17 -> Q3'26 | Y52: ='Revenue Build'!D17 -> Q4'26 | Z52: ='Revenue Build'!E17 -> Q1'27
A53: Revenue | B53: =Historical!B11 -> 7163 | C53: =Historical!C11 -> 7342 | D53: =Historical!D11 -> 7483 | E53: =Historical!E11 -> 7709 | F53: =Historical!F11 -> 7868 | G53: =Historical!G11 -> 7970 | H53: =Historical!H11 -> 7926 | I53: =Historical!I11 -> 7852 | ... V53: =Historical!V11 -> 12249 | W53: ='Revenue Build'!B22 -> 12706.7 | X53: ='Revenue Build'!C22 -> 13089.55 | Y53: ='Revenue Build'!D22 -> 13634.33 | Z53: ='Revenue Build'!E22 -> 13814.3
A54: Q2'26 Actual | W54: =Variance!C26 -> 12560
A56: Quarter | B56: =Historical!B4 -> Q1'21 | C56: =Historical!C4 -> Q2'21 | D56: =Historical!D4 -> Q3'21 | E56: =Historical!E4 -> Q4'21 | F56: =Historical!F4 -> Q1'22 | G56: =Historical!G4 -> Q2'22 | H56: =Historical!H4 -> Q3'22 | I56: =Historical!I4 -> Q4'22 | ... V56: =Historical!V4 -> Q1'26
A57: UCAN | B57: =Historical!B6 -> 3171 | C57: =Historical!C6 -> 3235 | D57: =Historical!D6 -> 3258 | E57: =Historical!E6 -> 3309 | F57: =Historical!F6 -> 3350 | G57: =Historical!G6 -> 3538 | H57: =Historical!H6 -> 3602 | I57: =Historical!I6 -> 3595 | ... V57: =Historical!V6 -> 5245
A58: EMEA | B58: =Historical!B7 -> 2344 | C58: =Historical!C7 -> 2400 | D58: =Historical!D7 -> 2432 | E58: =Historical!E7 -> 2523 | F58: =Historical!F7 -> 2562 | G58: =Historical!G7 -> 2457 | H58: =Historical!H7 -> 2376 | I58: =Historical!I7 -> 2350 | ... V58: =Historical!V7 -> 3998
A59: LATAM | B59: =Historical!B8 -> 837 | C59: =Historical!C8 -> 861 | D59: =Historical!D8 -> 915 | E59: =Historical!E8 -> 964 | F59: =Historical!F8 -> 999 | G59: =Historical!G8 -> 1030 | H59: =Historical!H8 -> 1024 | I59: =Historical!I8 -> 1017 | ... V59: =Historical!V8 -> 1497
A60: APAC | B60: =Historical!B9 -> 762 | C60: =Historical!C9 -> 799 | D60: =Historical!D9 -> 834 | E60: =Historical!E9 -> 871 | F60: =Historical!F9 -> 917 | G60: =Historical!G9 -> 908 | H60: =Historical!H9 -> 889 | I60: =Historical!I9 -> 857 | ... V60: =Historical!V9 -> 1509
A62: Quarter | B62: =Historical!B4 -> Q1'21 | C62: =Historical!C4 -> Q2'21 | D62: =Historical!D4 -> Q3'21 | E62: =Historical!E4 -> Q4'21 | F62: =Historical!F4 -> Q1'22 | G62: =Historical!G4 -> Q2'22 | H62: =Historical!H4 -> Q3'22 | I62: =Historical!I4 -> Q4'22 | ... V62: =Historical!V4 -> Q1'26
A63: Operating Margin % | B63: =Historical!B16 -> 0.274 | C63: =Historical!C16 -> 0.252 | D63: =Historical!D16 -> 0.235 | E63: =Historical!E16 -> 0.082 | F63: =Historical!F16 -> 0.251 | G63: =Historical!G16 -> 0.198 | H63: =Historical!H16 -> 0.193 | I63: =Historical!I16 -> 0.07 | ... V63: =Historical!V16 -> 0.323
A65: Bridge step | B65: Base (hidden) | C65: Increase | D65: Decrease | E65: Total | F65: Cumulative
A66: =Variance!A16 -> Base Forecast Total | B66: =0 -> 0 | C66: =0 -> 0 | D66: =0 -> 0 | E66: =F66 -> 12706.7 | F66: =Variance!B16 -> 12706.7
A67: =Variance!A17 -> UCAN variance | B67: =MIN(F66,F67) -> 12618.22 | C67: =MAX(0,F67-F66) -> 0 | D67: =MAX(0,F66-F67) -> 88.48 | E67: =0 -> 0 | F67: =F66+Variance!B17 -> 12618.22
A68: =Variance!A18 -> EMEA variance | B68: =MIN(F67,F68) -> 12548.14 | C68: =MAX(0,F68-F67) -> 0 | D68: =MAX(0,F67-F68) -> 70.08 | E68: =0 -> 0 | F68: =F67+Variance!B18 -> 12548.14
A69: =Variance!A19 -> LATAM variance | B69: =MIN(F68,F69) -> 12548.14 | C69: =MAX(0,F69-F68) -> 54.81 | D69: =MAX(0,F68-F69) -> 0 | E69: =0 -> 0 | F69: =F68+Variance!B19 -> 12602.95
A70: =Variance!A20 -> APAC variance | B70: =MIN(F69,F70) -> 12560 | C70: =MAX(0,F70-F69) -> 0 | D70: =MAX(0,F69-F70) -> 42.95 | E70: =0 -> 0 | F70: =F69+Variance!B20 -> 12560
A71: =Variance!A21 -> Actual Total | B71: =0 -> 0 | C71: =0 -> 0 | D71: =0 -> 0 | E71: =F71 -> 12560 | F71: =Variance!B21 -> 12560
A72: Chart 4 (Q2'26 Revenue Bridge) color key: green bars = favorable variance (actual beat forecast); red bars = unfavorable variance (actual missed forecast); blue bars = the Base Forecast Total and Actual Total endpoints. The "Base (hidden)" series is an invisible spacer that floats each bar; it is not a data point.
